<?xml version="1.0"?>
<robot name="mobile_robot" xmlns:xacro="http://www.ros.org/wiki/xacro">

  <!-- Base link -->
  <link name="base_link">
	<visual>
	  <geometry>
		<box size="0.4 0.3 0.1"/>
	  </geometry>
	  <material name="blue">
		<color rgba="0 0 0.8 1"/>
	  </material>
	</visual>
	<collision>
	  <geometry>
		<box size="0.4 0.3 0.1"/>
	  </geometry>
	</collision>
	<inertial>
	  <mass value="5.0"/>
	  <inertia ixx="0.05" ixy="0" ixz="0"
			   iyy="0.05" iyz="0"
			   izz="0.05"/>
	</inertial>
  </link>

  <!-- Left wheel -->
  <link name="left_wheel">
	<visual>
	  <geometry>
		<cylinder radius="0.05" length="0.04"/>
	  </geometry>
	  <material name="black">
		<color rgba="0 0 0 1"/>
	  </material>
	</visual>
	<collision>
	  <geometry>
		<cylinder radius="0.05" length="0.04"/>
	  </geometry>
	</collision>
	<inertial>
	  <mass value="0.5"/>
	  <inertia ixx="0.001" ixy="0" ixz="0"
			   iyy="0.001" iyz="0"
			   izz="0.001"/>
	</inertial>
  </link>

  <joint name="left_wheel_joint" type="continuous">
	<parent link="base_link"/>
	<child link="left_wheel"/>
	<origin xyz="0.0 0.17 -0.05" rpy="-1.5707 0 0"/>
	<axis xyz="0 0 1"/>
  </joint>

  <!-- Right wheel -->
  <link name="right_wheel">
	<visual>
	  <geometry>
		<cylinder radius="0.05" length="0.04"/>
	  </geometry>
	  <material name="black">
		<color rgba="0 0 0 1"/>
	  </material>
	</visual>
	<collision>
	  <geometry>
		<cylinder radius="0.05" length="0.04"/>
	  </geometry>
	</collision>
	<inertial>
	  <mass value="0.5"/>
	  <inertia ixx="0.001" ixy="0" ixz="0"
			   iyy="0.001" iyz="0"
			   izz="0.001"/>
	</inertial>
  </link>

  <joint name="right_wheel_joint" type="continuous">
	<parent link="base_link"/>
	<child link="right_wheel"/>
	<origin xyz="0.0 -0.17 -0.05" rpy="-1.5707 0 0"/>
	<axis xyz="0 0 1"/>
  </joint>

  <!-- Caster wheel -->
  <link name="caster_wheel">
	<visual>
	  <geometry>
		<sphere radius="0.025"/>
	  </geometry>
	  <material name="grey">
		<color rgba="0.5 0.5 0.5 1"/>
	  </material>
	</visual>
	<collision>
	  <geometry>
		<sphere radius="0.025"/>
	  </geometry>
	</collision>
	<inertial>
	  <mass value="0.1"/>
	  <inertia ixx="0.0001" ixy="0" ixz="0"
			   iyy="0.0001" iyz="0"
			   izz="0.0001"/>
	</inertial>
  </link>

  <joint name="caster_joint" type="fixed">
	<parent link="base_link"/>
	<child link="caster_wheel"/>
	<origin xyz="-0.15 0 -0.075" rpy="0 0 0"/>
  </joint>

<!-- Gazebo differential drive plugin -->
  <gazebo>
	<plugin
	  filename="gz-sim-diff-drive-system"
	  name="gz::sim::systems::DiffDrive">
	  <left_joint>left_wheel_joint</left_joint>
	  <right_joint>right_wheel_joint</right_joint>
	  <wheel_separation>0.34</wheel_separation>
	  <wheel_radius>0.05</wheel_radius>
	  <topic>cmd_vel</topic>
	  <odom_topic>odom</odom_topic>
	  <frame_id>odom</frame_id>
	  <child_frame_id>base_link</child_frame_id>
	</plugin>
  </gazebo>

</robot>
